Workbook

Sheet Данни
A1: ID клиент | B1: Клиент | C1: Служител | D1: Падеж | E1: Дължима сума | F1: Платена сума | G1: Статус контакт | H1: Обещана дата | I1: Бележка | J1: Остатък | K1: Дни просрочие | L1: Aging група | M1: В обхват 1-30 | N1: Приоритет | O1: Следващо действие | P1: % платено
A2: C001 | B2: Иван Петров | C2: Мария | D2: 46174 | E2: 227 | F2: 0 | G2: Обещание за плащане | H2: 46199 | I2: Няма отговор | J2: =MAX(0,E2-F2) | K2: =MAX(0,'Настройки'!$B$1-D2) | L2: =IF(K2=0,"Непросрочен",IF(K2<=5,"1-5 дни",IF(K2<=15,"6-15 дни",IF(K2<=30,"16-30 дни","30+ дни")))) | M2: =IF(AND(K2>=1,K2<=30,J2>0),"Да","Не") | N2: =IF(J2=0,"Приключен",IF(AND(K2>=16,K2<=30,J2>=500),"Висок",IF(OR(K2>=16,J2>=300),"Среден","Нисък"))) | O2: =IF(J2=0,"Няма действие",IF(G2="Неоткрит","Повторно обаждане + SMS",IF(G2="Обещание за плащане","Проследи обещанието",IF(G2="Отказва плащане","Ескалация към старши",IF(G2="Частично плащане","Договори остатъка","Стандартен контакт"))))) | P2: =IFERROR(F2/E2,0)
A3: C002 | B3: Георги Иванов | C3: Петър | D3: 46175 | E3: 364 | F3: 0 | G3: Отказва плащане | I3: Иска SMS с IBAN | J3: =MAX(0,E3-F3) | K3: =MAX(0,'Настройки'!$B$1-D3) | L3: =IF(K3=0,"Непросрочен",IF(K3<=5,"1-5 дни",IF(K3<=15,"6-15 дни",IF(K3<=30,"16-30 дни","30+ дни")))) | M3: =IF(AND(K3>=1,K3<=30,J3>0),"Да","Не") | N3: =IF(J3=0,"Приключен",IF(AND(K3>=16,K3<=30,J3>=500),"Висок",IF(OR(K3>=16,J3>=300),"Среден","Нисък"))) | O3: =IF(J3=0,"Няма действие",IF(G3="Неоткрит","Повторно обаждане + SMS",IF(G3="Обещание за плащане","Проследи обещанието",IF(G3="Отказва плащане","Ескалация към старши",IF(G3="Частично плащане","Договори остатъка","Стандартен контакт"))))) | P3: =IFERROR(F3/E3,0)
A4: C003 | B4: Десислава Николова | C4: Анна | D4: 46176 | E4: 501 | F4: 0 | G4: Неоткрит | I4: Ще плати след заплата | J4: =MAX(0,E4-F4) | K4: =MAX(0,'Настройки'!$B$1-D4) | L4: =IF(K4=0,"Непросрочен",IF(K4<=5,"1-5 дни",IF(K4<=15,"6-15 дни",IF(K4<=30,"16-30 дни","30+ дни")))) | M4: =IF(AND(K4>=1,K4<=30,J4>0),"Да","Не") | N4: =IF(J4=0,"Приключен",IF(AND(K4>=16,K4<=30,J4>=500),"Висок",IF(OR(K4>=16,J4>=300),"Среден","Нисък"))) | O4: =IF(J4=0,"Няма действие",IF(G4="Неоткрит","Повторно обаждане + SMS",IF(G4="Обещание за плащане","Проследи обещанието",IF(G4="Отказва плащане","Ескалация към старши",IF(G4="Частично плащане","Договори остатъка","Стандартен контакт"))))) | P4: =IFERROR(F4/E4,0)
A5: C004 | B5: Николай Димитров | C5: Георги | D5: 46177 | E5: 638 | F5: 638 | G5: Платено | I5: Платил частично | J5: =MAX(0,E5-F5) | K5: =MAX(0,'Настройки'!$B$1-D5) | L5: =IF(K5=0,"Непросрочен",IF(K5<=5,"1-5 дни",IF(K5<=15,"6-15 дни",IF(K5<=30,"16-30 дни","30+ дни")))) | M5: =IF(AND(K5>=1,K5<=30,J5>0),"Да","Не") | N5: =IF(J5=0,"Приключен",IF(AND(K5>=16,K5<=30,J5>=500),"Висок",IF(OR(K5>=16,J5>=300),"Среден","Нисък"))) | O5: =IF(J5=0,"Няма действие",IF(G5="Неоткрит","Повторно обаждане + SMS",IF(G5="Обещание за плащане","Проследи обещанието",IF(G5="Отказва плащане","Ескалация към старши",IF(G5="Частично плащане","Договори остатъка","Стандартен контакт"))))) | P5: =IFERROR(F5/E5,0)
A6: C005 | B6: Елена Георгиева | C6: Ива | D6: 46178 | E6: 775 | F6: 0 | G6: Отказва плащане | I6: Оспорва начисление | J6: =MAX(0,E6-F6) | K6: =MAX(0,'Настройки'!$B$1-D6) | L6: =IF(K6=0,"Непросрочен",IF(K6<=5,"1-5 дни",IF(K6<=15,"6-15 дни",IF(K6<=30,"16-30 дни","30+ дни")))) | M6: =IF(AND(K6>=1,K6<=30,J6>0),"Да","Не") | N6: =IF(J6=0,"Приключен",IF(AND(K6>=16,K6<=30,J6>=500),"Висок",IF(OR(K6>=16,J6>=300),"Среден","Нисък"))) | O6: =IF(J6=0,"Няма действие",IF(G6="Неоткрит","Повторно обаждане + SMS",IF(G6="Обещание за плащане","Проследи обещанието",IF(G6="Отказва плащане","Ескалация към старши",IF(G6="Частично плащане","Договори остатъка","Стандартен контакт"))))) | P6: =IFERROR(F6/E6,0)
A7: C006 | B7: Стефан Колев | C7: Мария | D7: 46174 | E7: 912 | F7: 0 | G7: Неоткрит | I7: Потвърдено плащане | J7: =MAX(0,E7-F7) | K7: =MAX(0,'Настройки'!$B$1-D7) | L7: =IF(K7=0,"Непросрочен",IF(K7<=5,"1-5 дни",IF(K7<=15,"6-15 дни",IF(K7<=30,"16-30 дни","30+ дни")))) | M7: =IF(AND(K7>=1,K7<=30,J7>0),"Да","Не") | N7: =IF(J7=0,"Приключен",IF(AND(K7>=16,K7<=30,J7>=500),"Висок",IF(OR(K7>=16,J7>=300),"Среден","Нисък"))) | O7: =IF(J7=0,"Няма действие",IF(G7="Неоткрит","Повторно обаждане + SMS",IF(G7="Обещание за плащане","Проследи обещанието",IF(G7="Отказва плащане","Ескалация към старши",IF(G7="Частично плащане","Договори остатъка","Стандартен контакт"))))) | P7: =IFERROR(F7/E7,0)
A8: C007 | B8: Виктория Стоянова | C8: Петър | D8: 46175 | E8: 1049 | F8: 398.62 | G8: Частично плащане | I8: Нужен втори контакт | J8: =MAX(0,E8-F8) | K8: =MAX(0,'Настройки'!$B$1-D8) | L8: =IF(K8=0,"Непросрочен",IF(K8<=5,"1-5 дни",IF(K8<=15,"6-15 дни",IF(K8<=30,"16-30 дни","30+ дни")))) | M8: =IF(AND(K8>=1,K8<=30,J8>0),"Да","Не") | N8: =IF(J8=0,"Приключен",IF(AND(K8>=16,K8<=30,J8>=500),"Висок",IF(OR(K8>=16,J8>=300),"Среден","Нисък"))) | O8: =IF(J8=0,"Няма действие",IF(G8="Неоткрит","Повторно обаждане + SMS",IF(G8="Обещание за плащане","Проследи обещанието",IF(G8="Отказва плащане","Ескалация към старши",IF(G8="Частично плащане","Договори остатъка","Стандартен контакт"))))) | P8: =IFERROR(F8/E8,0)
A9: C008 | B9: Христо Ангелов | C9: Анна | D9: 46176 | E9: 1186 | F9: 1186 | G9: Платено | I9: Да се провери лимит | J9: =MAX(0,E9-F9) | K9: =MAX(0,'Настройки'!$B$1-D9) | L9: =IF(K9=0,"Непросрочен",IF(K9<=5,"1-5 дни",IF(K9<=15,"6-15 дни",IF(K9<=30,"16-30 дни","30+ дни")))) | M9: =IF(AND(K9>=1,K9<=30,J9>0),"Да","Не") | N9: =IF(J9=0,"Приключен",IF(AND(K9>=16,K9<=30,J9>=500),"Висок",IF(OR(K9>=16,J9>=300),"Среден","Нисък"))) | O9: =IF(J9=0,"Няма действие",IF(G9="Неоткрит","Повторно обаждане + SMS",IF(G9="Обещание за плащане","Проследи обещанието",IF(G9="Отказва плащане","Ескалация към старши",IF(G9="Частично плащане","Договори остатъка","Стандартен контакт"))))) | P9: =IFERROR(F9/E9,0)
A10: C009 | B10: Борислав Тодоров | C10: Георги | D10: 46177 | E10: 1323 | F10: 0 | G10: Обаден | I10: Иска разсрочване | J10: =MAX(0,E10-F10) | K10: =MAX(0,'Настройки'!$B$1-D10) | L10: =IF(K10=0,"Непросрочен",IF(K10<=5,"1-5 дни",IF(K10<=15,"6-15 дни",IF(K10<=30,"16-30 дни","30+ дни")))) | M10: =IF(AND(K10>=1,K10<=30,J10>0),"Да","Не") | N10: =IF(J10=0,"Приключен",IF(AND(K10>=16,K10<=30,J10>=500),"Висок",IF(OR(K10>=16,J10>=300),"Среден","Нисък"))) | O10: =IF(J10=0,"Няма действие",IF(G10="Неоткрит","Повторно обаждане + SMS",IF(G10="Обещание за плащане","Проследи обещанието",IF(G10="Отказва плащане","Ескалация към старши",IF(G10="Частично плащане","Договори остатъка","Стандартен контакт"))))) | P10: =IFERROR(F10/E10,0)
A11: C010 | B11: Милена Христова | C11: Ива | D11: 46178 | E11: 1460 | F11: 321.2 | G11: Частично плащане | I11: Кратък разговор | J11: =MAX(0,E11-F11) | K11: =MAX(0,'Настройки'!$B$1-D11) | L11: =IF(K11=0,"Непросрочен",IF(K11<=5,"1-5 дни",IF(K11<=15,"6-15 дни",IF(K11<=30,"16-30 дни","30+ дни")))) | M11: =IF(AND(K11>=1,K11<=30,J11>0),"Да","Не") | N11: =IF(J11=0,"Приключен",IF(AND(K11>=16,K11<=30,J11>=500),"Висок",IF(OR(K11>=16,J11>=300),"Среден","Нисък"))) | O11: =IF(J11=0,"Няма действие",IF(G11="Неоткрит","Повторно обаждане + SMS",IF(G11="Обещание за плащане","Проследи обещанието",IF(G11="Отказва плащане","Ескалация към старши",IF(G11="Частично плащане","Договори остатъка","Стандартен контакт"))))) | P11: =IFERROR(F11/E11,0)
A12: C011 | B12: Красимир Василев | C12: Мария | D12: 46174 | E12: 147 | F12: 147 | G12: Платено | I12: Няма отговор | J12: =MAX(0,E12-F12) | K12: =MAX(0,'Настройки'!$B$1-D12) | L12: =IF(K12=0,"Непросрочен",IF(K12<=5,"1-5 дни",IF(K12<=15,"6-15 дни",IF(K12<=30,"16-30 дни","30+ дни")))) | M12: =IF(AND(K12>=1,K12<=30,J12>0),"Да","Не") | N12: =IF(J12=0,"Приключен",IF(AND(K12>=16,K12<=30,J12>=500),"Висок",IF(OR(K12>=16,J12>=300),"Среден","Нисък"))) | O12: =IF(J12=0,"Няма действие",IF(G12="Неоткрит","Повторно обаждане + SMS",IF(G12="Обещание за плащане","Проследи обещанието",IF(G12="Отказва плащане","Ескалация към старши",IF(G12="Частично плащане","Договори остатъка","Стандартен контакт"))))) | P12: =IFERROR(F12/E12,0)
A13: C012 | B13: Цветелина Маринова | C13: Петър | D13: 46175 | E13: 284 | F13: 0 | G13: Обаден | I13: Иска SMS с IBAN | J13: =MAX(0,E13-F13) | K13: =MAX(0,'Настройки'!$B$1-D13) | L13: =IF(K13=0,"Непросрочен",IF(K13<=5,"1-5 дни",IF(K13<=15,"6-15 дни",IF(K13<=30,"16-30 дни","30+ дни")))) | M13: =IF(AND(K13>=1,K13<=30,J13>0),"Да","Не") | N13: =IF(J13=0,"Приключен",IF(AND(K13>=16,K13<=30,J13>=500),"Висок",IF(OR(K13>=16,J13>=300),"Среден","Нисък"))) | O13: =IF(J13=0,"Няма действие",IF(G13="Неоткрит","Повторно обаждане + SMS",IF(G13="Обещание за плащане","Проследи обещанието",IF(G13="Отказва плащане","Ескалация към старши",IF(G13="Частично плащане","Договори остатъка","Стандартен контакт"))))) | P13: =IFERROR(F13/E13,0)
A14: C013 | B14: Даниел Илиев | C14: Анна | D14: 46176 | E14: 421 | F14: 193.66 | G14: Частично плащане | I14: Ще плати след заплата | J14: =MAX(0,E14-F14) | K14: =MAX(0,'Настройки'!$B$1-D14) | L14: =IF(K14=0,"Непросрочен",IF(K14<=5,"1-5 дни",IF(K14<=15,"6-15 дни",IF(K14<=30,"16-30 дни","30+ дни")))) | M14: =IF(AND(K14>=1,K14<=30,J14>0),"Да","Не") | N14: =IF(J14=0,"Приключен",IF(AND(K14>=16,K14<=30,J14>=500),"Висок",IF(OR(K14>=16,J14>=300),"Среден","Нисък"))) | O14: =IF(J14=0,"Няма действие",IF(G14="Неоткрит","Повторно обаждане + SMS",IF(G14="Обещание за плащане","Проследи обещанието",IF(G14="Отказва плащане","Ескалация към старши",IF(G14="Частично плащане","Договори остатъка","Стандартен контакт"))))) | P14: =IFERROR(F14/E14,0)
A15: C014 | B15: Надежда Попова | C15: Георги | D15: 46177 | E15: 558 | F15: 0 | G15: Неоткрит | I15: Платил частично | J15: =MAX(0,E15-F15) | K15: =MAX(0,'Настройки'!$B$1-D15) | L15: =IF(K15=0,"Непросрочен",IF(K15<=5,"1-5 дни",IF(K15<=15,"6-15 дни",IF(K15<=30,"16-30 дни","30+ дни")))) | M15: =IF(AND(K15>=1,K15<=30,J15>0),"Да","Не") | N15: =IF(J15=0,"Приключен",IF(AND(K15>=16,K15<=30,J15>=500),"Висок",IF(OR(K15>=16,J15>=300),"Среден","Нисък"))) | O15: =IF(J15=0,"Няма действие",IF(G15="Неоткрит","Повторно обаждане + SMS",IF(G15="Обещание за плащане","Проследи обещанието",IF(G15="Отказва плащане","Ескалация към старши",IF(G15="Частично плащане","Договори остатъка","Стандартен контакт"))))) | P15: =IFERROR(F15/E15,0)
A16: C015 | B16: Калоян Михайлов | C16: Ива | D16: 46178 | E16: 695 | F16: 34.75 | G16: Обещание за плащане | H16: 46201 | I16: Оспорва начисление | J16: =MAX(0,E16-F16) | K16: =MAX(0,'Настройки'!$B$1-D16) | L16: =IF(K16=0,"Непросрочен",IF(K16<=5,"1-5 дни",IF(K16<=15,"6-15 дни",IF(K16<=30,"16-30 дни","30+ дни")))) | M16: =IF(AND(K16>=1,K16<=30,J16>0),"Да","Не") | N16: =IF(J16=0,"Приключен",IF(AND(K16>=16,K16<=30,J16>=500),"Висок",IF(OR(K16>=16,J16>=300),"Среден","Нисък"))) | O16: =IF(J16=0,"Няма действие",IF(G16="Неоткрит","Повторно обаждане + SMS",IF(G16="Обещание за плащане","Проследи обещанието",IF(G16="Отказва плащане","Ескалация към старши",IF(G16="Частично плащане","Договори остатъка","Стандартен контакт"))))) | P16: =IFERROR(F16/E16,0)
A17: C016 | B17: Радостина Алексиева | C17: Мария | D17: 46174 | E17: 832 | F17: 0 | G17: Отказва плащане | I17: Потвърдено плащане | J17: =MAX(0,E17-F17) | K17: =MAX(0,'Настройки'!$B$1-D17) | L17: =IF(K17=0,"Непросрочен",IF(K17<=5,"1-5 дни",IF(K17<=15,"6-15 дни",IF(K17<=30,"16-30 дни","30+ дни")))) | M17: =IF(AND(K17>=1,K17<=30,J17>0),"Да","Не") | N17: =IF(J17=0,"Приключен",IF(AND(K17>=16,K17<=30,J17>=500),"Висок",IF(OR(K17>=16,J17>=300),"Среден","Нисък"))) | O17: =IF(J17=0,"Няма действие",IF(G17="Неоткрит","Повторно обаждане + SMS",IF(G17="Обещание за плащане","Проследи обещанието",IF(G17="Отказва плащане","Ескалация към старши",IF(G17="Частично плащане","Договори остатъка","Стандартен контакт"))))) | P17: =IFERROR(F17/E17,0)
A18: C017 | B18: Пламен Симеонов | C18: Петър | D18: 46175 | E18: 969 | F18: 0 | G18: Неоткрит | I18: Нужен втори контакт | J18: =MAX(0,E18-F18) | K18: =MAX(0,'Настройки'!$B$1-D18) | L18: =IF(K18=0,"Непросрочен",IF(K18<=5,"1-5 дни",IF(K18<=15,"6-15 дни",IF(K18<=30,"16-30 дни","30+ дни")))) | M18: =IF(AND(K18>=1,K18<=30,J18>0),"Да","Не") | N18: =IF(J18=0,"Приключен",IF(AND(K18>=16,K18<=30,J18>=500),"Висок",IF(OR(K18>=16,J18>=300),"Среден","Нисък"))) | O18: =IF(J18=0,"Няма действие",IF(G18="Неоткрит","Повторно обаждане + SMS",IF(G18="Обещание за плащане","Проследи обещанието",IF(G18="Отказва плащане","Ескалация към старши",IF(G18="Частично плащане","Договори остатъка","Стандартен контакт"))))) | P18: =IFERROR(F18/E18,0)
A19: C018 | B19: Мартин Йорданов | C19: Анна | D19: 46176 | E19: 1106 | F19: 55.3 | G19: Обещание за плащане | H19: 46200 | I19: Да се провери лимит | J19: =MAX(0,E19-F19) | K19: =MAX(0,'Настройки'!$B$1-D19) | L19: =IF(K19=0,"Непросрочен",IF(K19<=5,"1-5 дни",IF(K19<=15,"6-15 дни",IF(K19<=30,"16-30 дни","30+ дни")))) | M19: =IF(AND(K19>=1,K19<=30,J19>0),"Да","Не") | N19: =IF(J19=0,"Приключен",IF(AND(K19>=16,K19<=30,J19>=500),"Висок",IF(OR(K19>=16,J19>=300),"Среден","Нисък"))) | O19: =IF(J19=0,"Няма действие",IF(G19="Неоткрит","Повторно обаждане + SMS",IF(G19="Обещание за плащане","Проследи обещанието",IF(G19="Отказва плащане","Ескалация към старши",IF(G19="Частично плащане","Договори остатъка","Стандартен контакт"))))) | P19: =IFERROR(F19/E19,0)
A20: C019 | B20: Силвия Стоянова | C20: Георги | D20: 46177 | E20: 1243 | F20: 0 | G20: Отказва плащане | I20: Иска разсрочване | J20: =MAX(0,E20-F20) | K20: =MAX(0,'Настройки'!$B$1-D20) | L20: =IF(K20=0,"Непросрочен",IF(K20<=5,"1-5 дни",IF(K20<=15,"6-15 дни",IF(K20<=30,"16-30 дни","30+ дни")))) | M20: =IF(AND(K20>=1,K20<=30,J20>0),"Да","Не") | N20: =IF(J20=0,"Приключен",IF(AND(K20>=16,K20<=30,J20>=500),"Висок",IF(OR(K20>=16,J20>=300),"Среден","Нисък"))) | O20: =IF(J20=0,"Няма действие",IF(G20="Неоткрит","Повторно обаждане + SMS",IF(G20="Обещание за плащане","Проследи обещанието",IF(G20="Отказва плащане","Ескалация към старши",IF(G20="Частично плащане","Договори остатъка","Стандартен контакт"))))) | P20: =IFERROR(F20/E20,0)
A21: C020 | B21: Теодор Василев | C21: Ива | D21: 46178 | E21: 1380 | F21: 0 | G21: Неоткрит | I21: Кратък разговор | J21: =MAX(0,E21-F21) | K21: =MAX(0,'Настройки'!$B$1-D21) | L21: =IF(K21=0,"Непросрочен",IF(K21<=5,"1-5 дни",IF(K21<=15,"6-15 дни",IF(K21<=30,"16-30 дни","30+ дни")))) | M21: =IF(AND(K21>=1,K21<=30,J21>0),"Да","Не") | N21: =IF(J21=0,"Приключен",IF(AND(K21>=16,K21<=30,J21>=500),"Висок",IF(OR(K21>=16,J21>=300),"Среден","Нисък"))) | O21: =IF(J21=0,"Няма действие",IF(G21="Неоткрит","Повторно обаждане + SMS",IF(G21="Обещание за плащане","Проследи обещанието",IF(G21="Отказва плащане","Ескалация към старши",IF(G21="Частично плащане","Договори остатъка","Стандартен контакт"))))) | P21: =IFERROR(F21/E21,0)
A22: C021 | B22: Ралица Димова | C22: Мария | D22: 46174 | E22: 1517 | F22: 455.1 | G22: Частично плащане | I22: Няма отговор | J22: =MAX(0,E22-F22) | K22: =MAX(0,'Настройки'!$B$1-D22) | L22: =IF(K22=0,"Непросрочен",IF(K22<=5,"1-5 дни",IF(K22<=15,"6-15 дни",IF(K22<=30,"16-30 дни","30+ дни")))) | M22: =IF(AND(K22>=1,K22<=30,J22>0),"Да","Не") | N22: =IF(J22=0,"Приключен",IF(AND(K22>=16,K22<=30,J22>=500),"Висок",IF(OR(K22>=16,J22>=300),"Среден","Нисък"))) | O22: =IF(J22=0,"Няма действие",IF(G22="Неоткрит","Повторно обаждане + SMS",IF(G22="Обещание за плащане","Проследи обещанието",IF(G22="Отказва плащане","Ескалация към старши",IF(G22="Частично плащане","Договори остатъка","Стандартен контакт"))))) | P22: =IFERROR(F22/E22,0)
A23: C022 | B23: Асен Христов | C23: Петър | D23: 46175 | E23: 204 | F23: 204 | G23: Платено | I23: Иска SMS с IBAN | J23: =MAX(0,E23-F23) | K23: =MAX(0,'Настройки'!$B$1-D23) | L23: =IF(K23=0,"Непросрочен",IF(K23<=5,"1-5 дни",IF(K23<=15,"6-15 дни",IF(K23<=30,"16-30 дни","30+ дни")))) | M23: =IF(AND(K23>=1,K23<=30,J23>0),"Да","Не") | N23: =IF(J23=0,"Приключен",IF(AND(K23>=16,K23<=30,J23>=500),"Висок",IF(OR(K23>=16,J23>=300),"Среден","Нисък"))) | O23: =IF(J23=0,"Няма действие",IF(G23="Неоткрит","Повторно обаждане + SMS",IF(G23="Обещание за плащане","Проследи обещанието",IF(G23="Отказва плащане","Ескалация към старши",IF(G23="Частично плащане","Договори остатъка","Стандартен контакт"))))) | P23: =IFERROR(F23/E23,0)
A24: C023 | B24: Лилия Маринова | C24: Анна | D24: 46176 | E24: 341 | F24: 341 | G24: Платено | I24: Ще плати след заплата | J24: =MAX(0,E24-F24) | K24: =MAX(0,'Настройки'!$B$1-D24) | L24: =IF(K24=0,"Непросрочен",IF(K24<=5,"1-5 дни",IF(K24<=15,"6-15 дни",IF(K24<=30,"16-30 дни","30+ дни")))) | M24: =IF(AND(K24>=1,K24<=30,J24>0),"Да","Не") | N24: =IF(J24=0,"Приключен",IF(AND(K24>=16,K24<=30,J24>=500),"Висок",IF(OR(K24>=16,J24>=300),"Среден","Нисък"))) | O24: =IF(J24=0,"Няма действие",IF(G24="Неоткрит","Повторно обаждане + SMS",IF(G24="Обещание за плащане","Проследи обещанието",IF(G24="Отказва плащане","Ескалация към старши",IF(G24="Частично плащане","Договори остатъка","Стандартен контакт"))))) | P24: =IFERROR(F24/E24,0)
A25: C024 | B25: Таня Николова | C25: Георги | D25: 46177 | E25: 478 | F25: 258.12 | G25: Частично плащане | I25: Платил частично | J25: =MAX(0,E25-F25) | K25: =MAX(0,'Настройки'!$B$1-D25) | L25: =IF(K25=0,"Непросрочен",IF(K25<=5,"1-5 дни",IF(K25<=15,"6-15 дни",IF(K25<=30,"16-30 дни","30+ дни")))) | M25: =IF(AND(K25>=1,K25<=30,J25>0),"Да","Не") | N25: =IF(J25=0,"Приключен",IF(AND(K25>=16,K25<=30,J25>=500),"Висок",IF(OR(K25>=16,J25>=300),"Среден","Нисък"))) | O25: =IF(J25=0,"Няма действие",IF(G25="Неоткрит","Повторно обаждане + SMS",IF(G25="Обещание за плащане","Проследи обещанието",IF(G25="Отказва плащане","Ескалация към старши",IF(G25="Частично плащане","Договори остатъка","Стандартен контакт"))))) | P25: =IFERROR(F25/E25,0)
A26: C025 | B26: Валентин Костов | C26: Ива | D26: 46178 | E26: 615 | F26: 615 | G26: Платено | I26: Оспорва начисление | J26: =MAX(0,E26-F26) | K26: =MAX(0,'Настройки'!$B$1-D26) | L26: =IF(K26=0,"Непросрочен",IF(K26<=5,"1-5 дни",IF(K26<=15,"6-15 дни",IF(K26<=30,"16-30 дни","30+ дни")))) | M26: =IF(AND(K26>=1,K26<=30,J26>0),"Да","Не") | N26: =IF(J26=0,"Приключен",IF(AND(K26>=16,K26<=30,J26>=500),"Висок",IF(OR(K26>=16,J26>=300),"Среден","Нисък"))) | O26: =IF(J26=0,"Няма действие",IF(G26="Неоткрит","Повторно обаждане + SMS",IF(G26="Обещание за плащане","Проследи обещанието",IF(G26="Отказва плащане","Ескалация към старши",IF(G26="Частично плащане","Договори остатъка","Стандартен контакт"))))) | P26: =IFERROR(F26/E26,0)
A27: C026 | B27: Мария Тодорова | C27: Мария | D27: 46174 | E27: 752 | F27: 0 | G27: Обаден | I27: Потвърдено плащане | J27: =MAX(0,E27-F27) | K27: =MAX(0,'Настройки'!$B$1-D27) | L27: =IF(K27=0,"Непросрочен",IF(K27<=5,"1-5 дни",IF(K27<=15,"6-15 дни",IF(K27<=30,"16-30 дни","30+ дни")))) | M27: =IF(AND(K27>=1,K27<=30,J27>0),"Да","Не") | N27: =IF(J27=0,"Приключен",IF(AND(K27>=16,K27<=30,J27>=500),"Висок",IF(OR(K27>=16,J27>=300),"Среден","Нисък"))) | O27: =IF(J27=0,"Няма действие",IF(G27="Неоткрит","Повторно обаждане + SMS",IF(G27="Обещание за плащане","Проследи обещанието",IF(G27="Отказва плащане","Ескалация към старши",IF(G27="Частично плащане","Договори остатъка","Стандартен контакт"))))) | P27: =IFERROR(F27/E27,0)
A28: C027 | B28: Ивайло Попов | C28: Петър | D28: 46175 | E28: 889 | F28: 337.82 | G28: Частично плащане | I28: Нужен втори контакт | J28: =MAX(0,E28-F28) | K28: =MAX(0,'Настройки'!$B$1-D28) | L28: =IF(K28=0,"Непросрочен",IF(K28<=5,"1-5 дни",IF(K28<=15,"6-15 дни",IF(K28<=30,"16-30 дни","30+ дни")))) | M28: =IF(AND(K28>=1,K28<=30,J28>0),"Да","Не") | N28: =IF(J28=0,"Приключен",IF(AND(K28>=16,K28<=30,J28>=500),"Висок",IF(OR(K28>=16,J28>=300),"Среден","Нисък"))) | O28: =IF(J28=0,"Няма действие",IF(G28="Неоткрит","Повторно обаждане + SMS",IF(G28="Обещание за плащане","Проследи обещанието",IF(G28="Отказва плащане","Ескалация към старши",IF(G28="Частично плащане","Договори остатъка","Стандартен контакт"))))) | P28: =IFERROR(F28/E28,0)
A29: C028 | B29: Антония Илиева | C29: Анна | D29: 46176 | E29: 1026 | F29: 0 | G29: Неоткрит | I29: Да се провери лимит | J29: =MAX(0,E29-F29) | K29: =MAX(0,'Настройки'!$B$1-D29) | L29: =IF(K29=0,"Непросрочен",IF(K29<=5,"1-5 дни",IF(K29<=15,"6-15 дни",IF(K29<=30,"16-30 дни","30+ дни")))) | M29: =IF(AND(K29>=1,K29<=30,J29>0),"Да","Не") | N29: =IF(J29=0,"Приключен",IF(AND(K29>=16,K29<=30,J29>=500),"Висок",IF(OR(K29>=16,J29>=300),"Среден","Нисък"))) | O29: =IF(J29=0,"Няма действие",IF(G29="Неоткрит","Повторно обаждане + SMS",IF(G29="Обещание за плащане","Проследи обещанието",IF(G29="Отказва плащане","Ескалация към старши",IF(G29="Частично плащане","Договори остатъка","Стандартен контакт"))))) | P29: =IFERROR(F29/E29,0)
A30: C029 | B30: Габриела Пенева | C30: Георги | D30: 46177 | E30: 1163 | F30: 0 | G30: Обещание за плащане | H30: 46199 | I30: Иска разсрочване | J30: =MAX(0,E30-F30) | K30: =MAX(0,'Настройки'!$B$1-D30) | L30: =IF(K30=0,"Непросрочен",IF(K30<=5,"1-5 дни",IF(K30<=15,"6-15 дни",IF(K30<=30,"16-30 дни","30+ дни")))) | M30: =IF(AND(K30>=1,K30<=30,J30>0),"Да","Не") | N30: =IF(J30=0,"Приключен",IF(AND(K30>=16,K30<=30,J30>=500),"Висок",IF(OR(K30>=16,J30>=300),"Среден","Нисък"))) | O30: =IF(J30=0,"Няма действие",IF(G30="Неоткрит","Повторно обаждане + SMS",IF(G30="Обещание за плащане","Проследи обещанието",IF(G30="Отказва плащане","Ескалация към старши",IF(G30="Частично плащане","Договори остатъка","Стандартен контакт"))))) | P30: =IFERROR(F30/E30,0)
A31: C030 | B31: Димитър Стоев | C31: Ива | D31: 46178 | E31: 1300 | F31: 0 | G31: Отказва плащане | I31: Кратък разговор | J31: =MAX(0,E31-F31) | K31: =MAX(0,'Настройки'!$B$1-D31) | L31: =IF(K31=0,"Непросрочен",IF(K31<=5,"1-5 дни",IF(K31<=15,"6-15 дни",IF(K31<=30,"16-30 дни","30+ дни")))) | M31: =IF(AND(K31>=1,K31<=30,J31>0),"Да","Не") | N31: =IF(J31=0,"Приключен",IF(AND(K31>=16,K31<=30,J31>=500),"Висок",IF(OR(K31>=16,J31>=300),"Среден","Нисък"))) | O31: =IF(J31=0,"Няма действие",IF(G31="Неоткрит","Повторно обаждане + SMS",IF(G31="Обещание за плащане","Проследи обещанието",IF(G31="Отказва плащане","Ескалация към старши",IF(G31="Частично плащане","Договори остатъка","Стандартен контакт"))))) | P31: =IFERROR(F31/E31,0)
A32: C031 | B32: Петя Ангелова | C32: Мария | D32: 46174 | E32: 1437 | F32: 0 | G32: Неоткрит | I32: Няма отговор | J32: =MAX(0,E32-F32) | K32: =MAX(0,'Настройки'!$B$1-D32) | L32: =IF(K32=0,"Непросрочен",IF(K32<=5,"1-5 дни",IF(K32<=15,"6-15 дни",IF(K32<=30,"16-30 дни","30+ дни")))) | M32: =IF(AND(K32>=1,K32<=30,J32>0),"Да","Не") | N32: =IF(J32=0,"Приключен",IF(AND(K32>=16,K32<=30,J32>=500),"Висок",IF(OR(K32>=16,J32>=300),"Среден","Нисък"))) | O32: =IF(J32=0,"Няма действие",IF(G32="Неоткрит","Повторно обаждане + SMS",IF(G32="Обещание за плащане","Проследи обещанието",IF(G32="Отказва плащане","Ескалация към старши",IF(G32="Частично плащане","Договори остатъка","Стандартен контакт"))))) | P32: =IFERROR(F32/E32,0)
A33: C032 | B33: Явор Георгиев | C33: Петър | D33: 46175 | E33: 124 | F33: 0 | G33: Обещание за плащане | H33: 46198 | I33: Иска SMS с IBAN | J33: =MAX(0,E33-F33) | K33: =MAX(0,'Настройки'!$B$1-D33) | L33: =IF(K33=0,"Непросрочен",IF(K33<=5,"1-5 дни",IF(K33<=15,"6-15 дни",IF(K33<=30,"16-30 дни","30+ дни")))) | M33: =IF(AND(K33>=1,K33<=30,J33>0),"Да","Не") | N33: =IF(J33=0,"Приключен",IF(AND(K33>=16,K33<=30,J33>=500),"Висок",IF(OR(K33>=16,J33>=300),"Среден","Нисък"))) | O33: =IF(J33=0,"Няма действие",IF(G33="Неоткрит","Повторно обаждане + SMS",IF(G33="Обещание за плащане","Проследи обещанието",IF(G33="Отказва плащане","Ескалация към старши",IF(G33="Частично плащане","Договори остатъка","Стандартен контакт"))))) | P33: =IFERROR(F33/E33,0)
A34: C033 | B34: Росен Киров | C34: Анна | D34: 46176 | E34: 261 | F34: 7.83 | G34: Отказва плащане | I34: Ще плати след заплата | J34: =MAX(0,E34-F34) | K34: =MAX(0,'Настройки'!$B$1-D34) | L34: =IF(K34=0,"Непросрочен",IF(K34<=5,"1-5 дни",IF(K34<=15,"6-15 дни",IF(K34<=30,"16-30 дни","30+ дни")))) | M34: =IF(AND(K34>=1,K34<=30,J34>0),"Да","Не") | N34: =IF(J34=0,"Приключен",IF(AND(K34>=16,K34<=30,J34>=500),"Висок",IF(OR(K34>=16,J34>=300),"Среден","Нисък"))) | O34: =IF(J34=0,"Няма действие",IF(G34="Неоткрит","Повторно обаждане + SMS",IF(G34="Обещание за плащане","Проследи обещанието",IF(G34="Отказва плащане","Ескалация към старши",IF(G34="Частично плащане","Договори остатъка","Стандартен контакт"))))) | P34: =IFERROR(F34/E34,0)
A35: C034 | B35: Соня Михайлова | C35: Георги | D35: 46177 | E35: 398 | F35: 0 | G35: Неоткрит | I35: Платил частично | J35: =MAX(0,E35-F35) | K35: =MAX(0,'Настройки'!$B$1-D35) | L35: =IF(K35=0,"Непросрочен",IF(K35<=5,"1-5 дни",IF(K35<=15,"6-15 дни",IF(K35<=30,"16-30 дни","30+ дни")))) | M35: =IF(AND(K35>=1,K35<=30,J35>0),"Да","Не") | N35: =IF(J35=0,"Приключен",IF(AND(K35>=16,K35<=30,J35>=500),"Висок",IF(OR(K35>=16,J35>=300),"Среден","Нисък"))) | O35: =IF(J35=0,"Няма действие",IF(G35="Неоткрит","Повторно обаждане + SMS",IF(G35="Обещание за плащане","Проследи обещанието",IF(G35="Отказва плащане","Ескалация към старши",IF(G35="Частично плащане","Договори остатъка","Стандартен контакт"))))) | P35: =IFERROR(F35/E35,0)
A36: C035 | B36: Александър Борисов | C36: Ива | D36: 46178 | E36: 535 | F36: 117.7 | G36: Частично плащане | I36: Оспорва начисление | J36: =MAX(0,E36-F36) | K36: =MAX(0,'Настройки'!$B$1-D36) | L36: =IF(K36=0,"Непросрочен",IF(K36<=5,"1-5 дни",IF(K36<=15,"6-15 дни",IF(K36<=30,"16-30 дни","30+ дни")))) | M36: =IF(AND(K36>=1,K36<=30,J36>0),"Да","Не") | N36: =IF(J36=0,"Приключен",IF(AND(K36>=16,K36<=30,J36>=500),"Висок",IF(OR(K36>=16,J36>=300),"Среден","Нисък"))) | O36: =IF(J36=0,"Няма действие",IF(G36="Неоткрит","Повторно обаждане + SMS",IF(G36="Обещание за плащане","Проследи обещанието",IF(G36="Отказва плащане","Ескалация към старши",IF(G36="Частично плащане","Договори остатъка","Стандартен контакт"))))) | P36: =IFERROR(F36/E36,0)
A37: C036 | B37: Мирослав Данчев | C37: Мария | D37: 46174 | E37: 672 | F37: 672 | G37: Платено | I37: Потвърдено плащане | J37: =MAX(0,E37-F37) | K37: =MAX(0,'Настройки'!$B$1-D37) | L37: =IF(K37=0,"Непросрочен",IF(K37<=5,"1-5 дни",IF(K37<=15,"6-15 дни",IF(K37<=30,"16-30 дни","30+ дни")))) | M37: =IF(AND(K37>=1,K37<=30,J37>0),"Да","Не") | N37: =IF(J37=0,"Приключен",IF(AND(K37>=16,K37<=30,J37>=500),"Висок",IF(OR(K37>=16,J37>=300),"Среден","Нисък"))) | O37: =IF(J37=0,"Няма действие",IF(G37="Неоткрит","Повторно обаждане + SMS",IF(G37="Обещание за плащане","Проследи обещанието",IF(G37="Отказва плащане","Ескалация към старши",IF(G37="Частично плащане","Договори остатъка","Стандартен контакт"))))) | P37: =IFERROR(F37/E37,0)
A38: C037 | B38: Илия Павлов | C38: Петър | D38: 46175 | E38: 809 | F38: 809 | G38: Платено | I38: Нужен втори контакт | J38: =MAX(0,E38-F38) | K38: =MAX(0,'Настройки'!$B$1-D38) | L38: =IF(K38=0,"Непросрочен",IF(K38<=5,"1-5 дни",IF(K38<=15,"6-15 дни",IF(K38<=30,"16-30 дни","30+ дни")))) | M38: =IF(AND(K38>=1,K38<=30,J38>0),"Да","Не") | N38: =IF(J38=0,"Приключен",IF(AND(K38>=16,K38<=30,J38>=500),"Висок",IF(OR(K38>=16,J38>=300),"Среден","Нисък"))) | O38: =IF(J38=0,"Няма действие",IF(G38="Неоткрит","Повторно обаждане + SMS",IF(G38="Обещание за плащане","Проследи обещанието",IF(G38="Отказва плащане","Ескалация към старши",IF(G38="Частично плащане","Договори остатъка","Стандартен контакт"))))) | P38: =IFERROR(F38/E38,0)
A39: C038 | B39: Нели Христова | C39: Анна | D39: 46176 | E39: 946 | F39: 435.16 | G39: Частично плащане | I39: Да се провери лимит | J39: =MAX(0,E39-F39) | K39: =MAX(0,'Настройки'!$B$1-D39) | L39: =IF(K39=0,"Непросрочен",IF(K39<=5,"1-5 дни",IF(K39<=15,"6-15 дни",IF(K39<=30,"16-30 дни","30+ дни")))) | M39: =IF(AND(K39>=1,K39<=30,J39>0),"Да","Не") | N39: =IF(J39=0,"Приключен",IF(AND(K39>=16,K39<=30,J39>=500),"Висок",IF(OR(K39>=16,J39>=300),"Среден","Нисък"))) | O39: =IF(J39=0,"Няма действие",IF(G39="Неоткрит","Повторно обаждане + SMS",IF(G39="Обещание за плащане","Проследи обещанието",IF(G39="Отказва плащане","Ескалация към старши",IF(G39="Частично плащане","Договори остатъка","Стандартен контакт"))))) | P39: =IFERROR(F39/E39,0)
A40: C039 | B40: Биляна Василева | C40: Георги | D40: 46177 | E40: 1083 | F40: 1083 | G40: Платено | I40: Иска разсрочване | J40: =MAX(0,E40-F40) | K40: =MAX(0,'Настройки'!$B$1-D40) | L40: =IF(K40=0,"Непросрочен",IF(K40<=5,"1-5 дни",IF(K40<=15,"6-15 дни",IF(K40<=30,"16-30 дни","30+ дни")))) | M40: =IF(AND(K40>=1,K40<=30,J40>0),"Да","Не") | N40: =IF(J40=0,"Приключен",IF(AND(K40>=16,K40<=30,J40>=500),"Висок",IF(OR(K40>=16,J40>=300),"Среден","Нисък"))) | O40: =IF(J40=0,"Няма действие",IF(G40="Неоткрит","Повторно обаждане + SMS",IF(G40="Обещание за плащане","Проследи обещанието",IF(G40="Отказва плащане","Ескалация към старши",IF(G40="Частично плащане","Договори остатъка","Стандартен контакт"))))) | P40: =IFERROR(F40/E40,0)
...

Sheet Настройки
A1: Дата за упражнението | B1: 46197
A2: Цел събираемост | B2: 0.7
A3: Обхват на екипа | B3: 1-30 дни просрочие
A4: Падеж кредитна карта | B4: Фиксиран между 1-во и 5-то число
A6: Съвет | B6: Първо филтрирай M=Да и J>0, после приоритизирай N=Висок.

Sheet KPI
A1: KPI табло - събираемост кредитни карти
A3: Показател | B3: Стойност
A4: Общо възложена сума | B4: =SUM('Данни'!E:E)
A5: Общо събрана сума | B5: =SUM('Данни'!F:F)
A6: Остатък за събиране | B6: =SUM('Данни'!J:J)
A7: % събираемост | B7: =IFERROR(B5/B4,0)
A8: Клиенти в обхват 1-30 | B8: =COUNTIF('Данни'!M:M,"Да")
A9: Висок приоритет | B9: =COUNTIF('Данни'!N:N,"Висок")
A10: Извън обхват/приключени | B10: =COUNTIF('Данни'!M:M,"Не")
A13: Служител | B13: Брой клиенти | C13: Възложена сума | D13: Събрана сума | E13: Остатък | F13: % събираемост | G13: Висок приоритет
A14: Мария | B14: =COUNTIF('Данни'!C:C,A14) | C14: =SUMIF('Данни'!C:C,A14,'Данни'!E:E) | D14: =SUMIF('Данни'!C:C,A14,'Данни'!F:F) | E14: =SUMIF('Данни'!C:C,A14,'Данни'!J:J) | F14: =IFERROR(D14/C14,0) | G14: =COUNTIFS('Данни'!C:C,A14,'Данни'!N:N,"Висок")
A15: Петър | B15: =COUNTIF('Данни'!C:C,A15) | C15: =SUMIF('Данни'!C:C,A15,'Данни'!E:E) | D15: =SUMIF('Данни'!C:C,A15,'Данни'!F:F) | E15: =SUMIF('Данни'!C:C,A15,'Данни'!J:J) | F15: =IFERROR(D15/C15,0) | G15: =COUNTIFS('Данни'!C:C,A15,'Данни'!N:N,"Висок")
A16: Анна | B16: =COUNTIF('Данни'!C:C,A16) | C16: =SUMIF('Данни'!C:C,A16,'Данни'!E:E) | D16: =SUMIF('Данни'!C:C,A16,'Данни'!F:F) | E16: =SUMIF('Данни'!C:C,A16,'Данни'!J:J) | F16: =IFERROR(D16/C16,0) | G16: =COUNTIFS('Данни'!C:C,A16,'Данни'!N:N,"Висок")
A17: Георги | B17: =COUNTIF('Данни'!C:C,A17) | C17: =SUMIF('Данни'!C:C,A17,'Данни'!E:E) | D17: =SUMIF('Данни'!C:C,A17,'Данни'!F:F) | E17: =SUMIF('Данни'!C:C,A17,'Данни'!J:J) | F17: =IFERROR(D17/C17,0) | G17: =COUNTIFS('Данни'!C:C,A17,'Данни'!N:N,"Висок")
A18: Ива | B18: =COUNTIF('Данни'!C:C,A18) | C18: =SUMIF('Данни'!C:C,A18,'Данни'!E:E) | D18: =SUMIF('Данни'!C:C,A18,'Данни'!F:F) | E18: =SUMIF('Данни'!C:C,A18,'Данни'!J:J) | F18: =IFERROR(D18/C18,0) | G18: =COUNTIFS('Данни'!C:C,A18,'Данни'!N:N,"Висок")
A22: Aging група | B22: Брой клиенти | C22: Остатък | E22: Статус контакт | F22: Брой клиенти | G22: Остатък
A23: 1-5 дни | B23: =COUNTIF('Данни'!L:L,A23) | C23: =SUMIF('Данни'!L:L,A23,'Данни'!J:J) | E23: Неоткрит | F23: =COUNTIF('Данни'!G:G,E23) | G23: =SUMIF('Данни'!G:G,E23,'Данни'!J:J)
A24: 6-15 дни | B24: =COUNTIF('Данни'!L:L,A24) | C24: =SUMIF('Данни'!L:L,A24,'Данни'!J:J) | E24: Обаден | F24: =COUNTIF('Данни'!G:G,E24) | G24: =SUMIF('Данни'!G:G,E24,'Данни'!J:J)
A25: 16-30 дни | B25: =COUNTIF('Данни'!L:L,A25) | C25: =SUMIF('Данни'!L:L,A25,'Данни'!J:J) | E25: Обещание за плащане | F25: =COUNTIF('Данни'!G:G,E25) | G25: =SUMIF('Данни'!G:G,E25,'Данни'!J:J)
A26: 30+ дни | B26: =COUNTIF('Данни'!L:L,A26) | C26: =SUMIF('Данни'!L:L,A26,'Данни'!J:J) | E26: Частично плащане | F26: =COUNTIF('Данни'!G:G,E26) | G26: =SUMIF('Данни'!G:G,E26,'Данни'!J:J)
A27: Непросрочен | B27: =COUNTIF('Данни'!L:L,A27) | C27: =SUMIF('Данни'!L:L,A27,'Данни'!J:J) | E27: Отказва плащане | F27: =COUNTIF('Данни'!G:G,E27) | G27: =SUMIF('Данни'!G:G,E27,'Данни'!J:J)
E28: Платено | F28: =COUNTIF('Данни'!G:G,E28) | G28: =SUMIF('Данни'!G:G,E28,'Данни'!J:J)

Sheet Задачи
A1: Задачи за подготовка
A3: Стъпка | B3: Описание
A4: Цел | B4: Упражнение за интервю: ръководител екип събираемост, кредитни карти с падеж 1-5 число и работа до 30 дни просрочие.
A5: 1 | B5: В лист Данни филтрирай само клиентите с "В обхват 1-30" = Да и Остатък > 0.
A6: 2 | B6: Сортирай по Приоритет = Висок и после по Остатък от най-голям към най-малък.
A7: 3 | B7: Обясни кои 5 клиента би дал първо за контакт и защо.
A8: 4 | B8: В KPI виж кой служител има най-висок % събираемост и кой има най-голям остатък.
A9: 5 | B9: Направи Pivot Table: Rows = Служител, Values = Sum of Остатък и Sum of Платена сума.
A10: 6 | B10: Направи втори Pivot Table: Rows = Aging група, Columns = Приоритет, Values = Count of ID клиент.
A11: 7 | B11: Подготви кратък управленски коментар: риск, приоритети за деня, кой служител има нужда от подкрепа.
A12: Формула за остатък | B12: =MAX(0,E2-F2)
A13: Формула за дни просрочие | B13: =MAX(0,'Настройки'!$B$1-D2)
A14: Формула за обхват | B14: =IF(AND(K2>=1,K2<=30,J2>0),"Да","Не")
